Traceback (most recent call last):
  File "/home/mb2023/my_hpc_projects/synthcity-docker-project/generating.py", line 11, in <module>
    df = pd.read_csv(file_path)
         ^^^^^^^^^^^^^^^^^^^^^^
  File "/home/mb2023/.conda/envs/synth_env/lib/python3.11/site-packages/pandas/io/parsers/readers.py", line 1026, in read_csv
    return _read(filepath_or_buffer, kwds)
           ^^^^^^^^^^^^^^^^^^^^^^^^^^^^^^^
  File "/home/mb2023/.conda/envs/synth_env/lib/python3.11/site-packages/pandas/io/parsers/readers.py", line 620, in _read
    parser = TextFileReader(filepath_or_buffer, **kwds)
             ^^^^^^^^^^^^^^^^^^^^^^^^^^^^^^^^^^^^^^^^^^
  File "/home/mb2023/.conda/envs/synth_env/lib/python3.11/site-packages/pandas/io/parsers/readers.py", line 1620, in __init__
    self._engine = self._make_engine(f, self.engine)
                   ^^^^^^^^^^^^^^^^^^^^^^^^^^^^^^^^^
  File "/home/mb2023/.conda/envs/synth_env/lib/python3.11/site-packages/pandas/io/parsers/readers.py", line 1898, in _make_engine
    return mapping[engine](f, **self.options)
           ^^^^^^^^^^^^^^^^^^^^^^^^^^^^^^^^^^
  File "/home/mb2023/.conda/envs/synth_env/lib/python3.11/site-packages/pandas/io/parsers/c_parser_wrapper.py", line 93, in __init__
    self._reader = parsers.TextReader(src, **kwds)
                   ^^^^^^^^^^^^^^^^^^^^^^^^^^^^^^^
  File "pandas/_libs/parsers.pyx", line 574, in pandas._libs.parsers.TextReader.__cinit__
  File "pandas/_libs/parsers.pyx", line 663, in pandas._libs.parsers.TextReader._get_header
  File "pandas/_libs/parsers.pyx", line 874, in pandas._libs.parsers.TextReader._tokenize_rows
  File "pandas/_libs/parsers.pyx", line 891, in pandas._libs.parsers.TextReader._check_tokenize_status
  File "pandas/_libs/parsers.pyx", line 2053, in pandas._libs.parsers.raise_parser_error
UnicodeDecodeError: 'utf-8' codec can't decode bytes in position 15-16: invalid continuation byte
